penai.PermissionDeniedError: Error code: 403 - {'error': {'message': 'Project `proj_EcupcW5u3O3Jl7yj92KMqRd9` does not have access to model `text-embedding-ada-002`', 'type': 'invalid_request_error', 'param': None, 'code': 'model_not_found'}}
Traceback:
File "/home/runner/workspace/.pythonlibs/lib/python3.11/site-packages/streamlit/runtime/scriptrunner/exec_code.py", line 121, in exec_func_with_error_handling
    result = func()
             ^^^^^^
File "/home/runner/workspace/.pythonlibs/lib/python3.11/site-packages/streamlit/runtime/scriptrunner/script_runner.py", line 593, in code_to_exec
    exec(code, module.__dict__)
File "/home/runner/workspace/app.py", line 54, in <module>
    st.session_state.vector_store = create_vector_store(text_chunks)
                                    ^^^^^^^^^^^^^^^^^^^^^^^^^^^^^^^^
File "/home/runner/workspace/utils.py", line 36, in create_vector_store
    vector_store = FAISS.from_texts(text_chunks, embeddings)
                   ^^^^^^^^^^^^^^^^^^^^^^^^^^^^^^^^^^^^^^^^^
File "/home/runner/workspace/.pythonlibs/lib/python3.11/site-packages/langchain_community/vectorstores/faiss.py", line 1043, in from_texts
    embeddings = embedding.embed_documents(texts)
                 ^^^^^^^^^^^^^^^^^^^^^^^^^^^^^^^^
File "/home/runner/workspace/.pythonlibs/lib/python3.11/site-packages/langchain_community/embeddings/openai.py", line 671, in embed_documents
    return self._get_len_safe_embeddings(texts, engine=engine)
           ^^^^^^^^^^^^^^^^^^^^^^^^^^^^^^^^^^^^^^^^^^^^^^^^^^^
File "/home/runner/workspace/.pythonlibs/lib/python3.11/site-packages/langchain_community/embeddings/openai.py", line 497, in _get_len_safe_embeddings
    response = embed_with_retry(
               ^^^^^^^^^^^^^^^^^
File "/home/runner/workspace/.pythonlibs/lib/python3.11/site-packages/langchain_community/embeddings/openai.py", line 120, in embed_with_retry
    return embeddings.client.create(**kwargs)
           ^^^^^^^^^^^^^^^^^^^^^^^^^^^^^^^^^^
File "/home/runner/workspace/.pythonlibs/lib/python3.11/site-packages/openai/resources/embeddings.py", line 128, in create
    return self._post(
           ^^^^^^^^^^^
File "/home/runner/workspace/.pythonlibs/lib/python3.11/site-packages/openai/_base_client.py", line 1242, in post
    return cast(ResponseT, self.request(cast_to, opts, stream=stream, stream_cls=stream_cls))
                           ^^^^^^^^^^^^^^^^^^^^^^^^^^^^^^^^^^^^^^^^^^^^^^^^^^^^^^^^^^^^^^^^^
File "/home/runner/workspace/.pythonlibs/lib/python3.11/site-packages/openai/_base_client.py", line 919, in request
    return self._request(
           ^^^^^^^^^^^^^^
File "/home/runner/workspace/.pythonlibs/lib/python3.11/site-packages/openai/_base_client.py", line 1023, in _request
    raise self._make_status_error_from_response(err.response) from None